Workbook

Sheet Calculator
A1: SETNAYAN — Papic 5-Year Storage Cost Model
A2: Edit the BLUE cells. YELLOW = highest-impact levers. Cost is dominated by the cold-tail (compression × months). R2 egress = $0.
A4: INPUTS (edit blue cells)
A5: Guest count (pax) | B5: 250 | C5: Papic Guest flat-price ceiling = 250
A6: MB per guest (24 photos + 10×5s clips) | B6: 190 | C6: Source: 10_Papic_Feature_Specification.md
A7: Files uploaded per guest | B7: 34 | C7: 24 photos + 10 clips
A8: Retention (years) | B8: 5 | C8: PH photographers keep originals 5+ yrs
A9: Hot window — full-res (months) | B9: 3 | C9: Full-res, on Standard, then tier to cold
A10: Cold-tail compression (% of original kept) | B10: 0.35 | C10: THE big lever. 100%=no compress
A11: R2 Standard rate ($/GB-month) | B11: 0.015 | C11: Cloudflare R2 published
A12: R2 Infrequent-Access rate ($/GB-month) | B12: 0.01 | C12: Cloudflare R2 published
A13: Class A write rate ($ per million ops) | B13: 4.5 | C13: Uploads (PUTs)
A14: FX (PHP per USD) | B14: 57 | C14: ~June 2026
A15: Papic Guest SKU price (₱) | B15: 2999 | C15: Live-site price
A17: STORAGE VOLUME
A18: Full-res data (GB) | B18: =B5*B6/1000 -> 47.5
A19: Total retention (months) | B19: =B8*12 -> 60
A20: Cold-tail months | B20: =B19-B9 -> 57
A21: Cold-tail data (GB, compressed) | B21: =B18*B10 -> 16.625
A23: 5-YEAR COST (USD)
A24: Hot storage — full-res on Standard | B24: =B18*B9*B11 -> 2.1375
A25: Cold storage — compressed on IA | B25: =B21*B20*B12 -> 9.47625
A26: Write operations — Class A | B26: =B5*B7/1000000*B13 -> 0.03825
A27: Egress (R2 = free) | B27: 0
A28: TOTAL storage cost (USD) | B28: =SUM(B24:B27) -> 11.652
A30: RESULT (₱)
A31: Total 5-year cost / event (₱) | B31: =B28*B14 -> 664.164
A32: Cost per guest (₱) | B32: =B31/B5 -> 2.656656
A33: SKU price (₱) | B33: =B15 -> 2999
A34: Gross margin (₱) | B34: =B33-B31 -> 2334.836
A35: Gross margin (%) | B35: =B34/B33 -> 0.77853818
A37: Notes & sources
A38: • R2: Cloudflare R2 — Standard $0.015/GB-mo · Infrequent Access $0.010/GB-mo · egress $0.
A39: • 190 MB/guest from 10_Papic_Feature_Specification.md (24 photos + 10×5s clips).
A40: • Storage cost is dominated by the cold-tail: compression % and months. Set compression to 100% to model full-res-forever.
A41: • See the Scenarios tab for the 3 policy options (full-res vs tiered/compressed) side-by-side.

Sheet Scenarios
A1: Papic 5-Year Storage — 3 Policy Options
A3: Parameter | B3: A — Full-res / Standard | C3: B — Compress 35% + IA | D3: C — Compress 18% + IA
A5: Guest count (pax) | B5: =Calculator!$B$5 -> 250 | C5: =Calculator!$B$5 -> 250 | D5: =Calculator!$B$5 -> 250
A6: MB per guest | B6: =Calculator!$B$6 -> 190 | C6: =Calculator!$B$6 -> 190 | D6: =Calculator!$B$6 -> 190
A7: Full-res data (GB) | B7: =B5*B6/1000 -> 47.5 | C7: =C5*C6/1000 -> 47.5 | D7: =D5*D6/1000 -> 47.5
A8: Retention (months) | B8: =Calculator!$B$19 -> 60 | C8: =Calculator!$B$19 -> 60 | D8: =Calculator!$B$19 -> 60
A9: Standard rate ($/GB-mo) | B9: =Calculator!$B$11 -> 0.015 | C9: =Calculator!$B$11 -> 0.015 | D9: =Calculator!$B$11 -> 0.015
A10: IA rate ($/GB-mo) | B10: =Calculator!$B$12 -> 0.01 | C10: =Calculator!$B$12 -> 0.01 | D10: =Calculator!$B$12 -> 0.01
A11: FX (₱/USD) | B11: =Calculator!$B$14 -> 57 | C11: =Calculator!$B$14 -> 57 | D11: =Calculator!$B$14 -> 57
A12: SKU price (₱) | B12: =Calculator!$B$15 -> 2999 | C12: =Calculator!$B$15 -> 2999 | D12: =Calculator!$B$15 -> 2999
A14: Hot window — full-res (months) | B14: 60 | C14: 3 | D14: 3
A15: Cold-tail compression (% kept) | B15: 1 | C15: 0.35 | D15: 0.18
A16: Cold-tail rate ($/GB-mo) | B16: =B9 -> 0.015 | C16: =C10 -> 0.01 | D16: =D10 -> 0.01
A18: Cold-tail months | B18: =B8-B14 -> 0 | C18: =C8-C14 -> 57 | D18: =D8-D14 -> 57
A19: Cold-tail data (GB) | B19: =B7*B15 -> 47.5 | C19: =C7*C15 -> 16.625 | D19: =D7*D15 -> 8.55
A20: Hot cost (USD) | B20: =B7*B14*B9 -> 42.75 | C20: =C7*C14*C9 -> 2.1375 | D20: =D7*D14*D9 -> 2.1375
A21: Cold cost (USD) | B21: =B19*B18*B16 -> 0 | C21: =C19*C18*C16 -> 9.47625 | D21: =D19*D18*D16 -> 4.8735
A22: Write ops (USD) | B22: =Calculator!$B$26 -> 0.03825 | C22: =Calculator!$B$26 -> 0.03825 | D22: =Calculator!$B$26 -> 0.03825
A23: Total (USD) | B23: =SUM(B20:B22) -> 42.78825 | C23: =SUM(C20:C22) -> 11.652 | D23: =SUM(D20:D22) -> 7.04925
A24: Total 5-yr cost / event (₱) | B24: =B23*B11 -> 2438.9302 | C24: =C23*C11 -> 664.164 | D24: =D23*D11 -> 401.80725
A25: Gross margin (₱) | B25: =B12-B24 -> 560.06975 | C25: =C12-C24 -> 2334.836 | D25: =D12-D24 -> 2597.1928
A26: Gross margin (%) | B26: =B25/B12 -> 0.18675217 | C26: =C25/C12 -> 0.77853818 | D26: =D25/D12 -> 0.86601959
A28: Policy A = keep every original full-res on Standard for 5 yrs. B = realistic tiering. C = aggressive compression (your spec’s ₱356 basis).

Sheet BreakEven
A1: SETNAYAN — Worst-Case Break-Even (everyone free-rides, nobody pays)
A2: Edit blue cells. Scenario: 100 vendors join, none buy Pro/Enterprise, couples use only free tools, vendors never spend tokens.
A4: ① FIXED MONTHLY PLATFORM COST (runs whether you have 0 or 10,000 users)
A5: Vercel — hosting | B5: 1140 | C5: ~$20/mo · owner confirm
A6: Supabase — database + auth | B6: 1425 | C6: ~$25/mo
A7: Resend — email | B7: 1140 | C7: ~$20/mo (free under 3k emails)
A8: Sentry — error monitoring | B8: 1500 | C8: 0035 observability spec
A9: PostHog — product analytics | B9: 1000 | C9: 0035 spec
A10: Better Stack — uptime/status | B10: 1000 | C10: 0035 spec
A11: Cloudflare — base + R2 operations | B11: 500 | C11: estimate
A12: Domains (amortized) | B12: 100 | C12: setnayan.com/.ph
A13: AI APIs — base (planner/contract) | B13: 500 | C13: free planner is deterministic ≈₱0
A14: Misc / buffer | B14: 1000
A15: TOTAL FIXED / month | B15: =SUM(B5:B14) -> 9305
A17: ② MARGINAL STORAGE COST OF FREE USERS (this is the part you fear — watch how tiny it is)
A18: R2 storage rate (₱/GB-month) | B18: =Calculator!B11*Calculator!B14 -> 0.855 | C18: Standard rate × FX (from Calculator)
A19: Free vendors (#) | B19: 100
A20: Avg storage per free vendor (GB) | B20: 0.2 | C20: logo + ~20 portfolio images
A21: Free couples / events (#) | B21: 100
A22: Avg storage per free couple (GB) | B22: 0.5 | C22: website + mood board + a few photos (no paid Papic)
A23: Vendor storage cost / month | B23: =B19*B20*B18 -> 17.1
A24: Couple storage cost / month | B24: =B21*B22*B18 -> 42.75
A25: TOTAL MARGINAL / month | B25: =B23+B24 -> 59.85
A26: → Cost to carry 1 free vendor / YEAR | B26: =B20*B18*12 -> 2.052
A27: → Cost to carry 1 free couple / YEAR | B27: =B22*B18*12 -> 5.13
A29: ③ REVENUE THIS MONTH (worst case = all zero)
A30: Pro vendors (#) | B30: 0
A31: Pro price (₱/month) | B31: 6000 | C31: ₱6,000/28d — DB canon
A32: Enterprise vendors (#) | B32: 0
A33: Enterprise price (₱/month) | B33: 10000
A34: Paid SKU sales (# / month) | B34: 0 | C34: Papic, Panood, monogram, etc.
A35: Avg SKU price (₱) | B35: 2999
A36: Token revenue (₱/month) | B36: 0
A37: Setnayan Pay fees (₱/month) | B37: 0
A38: TOTAL REVENUE / month | B38: =B30*B31+B32*B33+B34*B35+B36+B37 -> 0
A40: ④ RESULT
A41: Total monthly cost (fixed + marginal) | B41: =B15+B25 -> 9364.85
A42: Total monthly revenue | B42: =B38 -> 0
A43: NET monthly profit / (loss) | B43: =B38-B41 -> -9364.85
A44: Break-even: Pro vendors needed | B44: =B41/B31 -> 1.5608083
...
