Workbook

Sheet Pricing Overview
A1: Setnayan · Master Pricing & Cost Workbook
A2: All amounts in PHP (Philippine pesos) · 2026-05-08 · v1
A4: Iteration / Folder | B4: SKU / Product | C4: What couple gets | D4: Couple price (₱) | E4: Cost to deliver (₱) | F4: Margin (₱) | G4: Margin %
A5: 0001 · Guest List Management | B5: Included in base tier | C5: Add/edit/categorize guests, role taxonomy, CSV import, household grouping. No per-couple charge — included in any Paparazzi tier. | D5: 0 | E5: 0 | F5: =D5-E5 | G5: =IF(D5=0,0,(D5-E5)/D5)
A6: 0002 · QR & Personal Invitation Site | B6: Included in base tier | C6: Personal invitation site for every guest with QR, RSVP, schedule, dress code, photo placeholders. Included with any Paparazzi tier. | D6: 0 | E6: 0 | F6: =D6-E6 | G6: =IF(D6=0,0,(D6-E6)/D6)
A7: 0002 · QR Token Re-issue | B7: Per-guest token rotation | C7: Couple rotates one guest's QR if their card is lost. Free. | D7: 0 | E7: 0 | F7: =D7-E7 | G7: =IF(D7=0,0,(D7-E7)/D7)
A8: 0003 · Invitation Widgets Editor | B8: Editor (free) | C8: 10 widgets configurable in 3-panel editor with live preview. Basic tier of every widget is included with Paparazzi tier. | D8: 0 | E8: 0 | F8: =D8-E8 | G8: =IF(D8=0,0,(D8-E8)/D8)
A9: 0003 · Hero Monogram Pro animation | B9: Trace-then-morph animation | C9: Names trace in handwritten, morph into the monogram, frame draws around. 6s loop on every guest's invitation. | D9: 99 | E9: 0 | F9: =D9-E9 | G9: =IF(D9=0,0,(D9-E9)/D9)
A10: 0003 · Venue Pro Waze deep-links | B10: Native map app deep-links | C10: Venue cards open natively in Waze + Google Maps instead of generic 'Get directions'. | D10: 99 | E10: 0 | F10: =D10-E10 | G10: =IF(D10=0,0,(D10-E10)/D10)
A11: 0003 · Pro Bundle (Hero animation + Venue Waze) | B11: Bundle of two original Pro upgrades | C11: Trace-then-morph animation + Venue Waze. Saves ₱49 vs buying both individually. Superseded by Hero Monogram Pro Bundle for couples buying multiple Hero upgrades. | D11: 149 | E11: 0 | F11: =D11-E11 | G11: =IF(D11=0,0,(D11-E11)/D11)
A12: 0004 · LED Background Maker | B12: Editor + drafts (free) | C12: 10 templates, customization, live preview. Drafts and previews are always free; couple only pays per render. | D12: 0 | E12: 0 | F12: =D12-E12 | G12: =IF(D12=0,0,(D12-E12)/D12)
A13: 0004 · LED Background — 1080p render | B13: 1920×1080 H.264 30s loop | C13: ~30 MB, ~3 min render time. Suitable for projection screens, prep rooms, smaller LED panels. | D13: 249 | E13: 25 | F13: =D13-E13 | G13: =IF(D13=0,0,(D13-E13)/D13)
A14: 0004 · LED Background — 4K render | B14: 3840×2160 H.264 30s loop | C14: ~70 MB, ~5 min render time. Standard LED wall resolution at most venues. | D14: 399 | E14: 40 | F14: =D14-E14 | G14: =IF(D14=0,0,(D14-E14)/D14)
A15: 0004 · LED Background — 8K render | B15: 7680×4320 H.264 30s loop | C15: ~120 MB, ~8 min render time. Premium / high-end LED walls. | D15: 599 | E15: 60 | F15: =D15-E15 | G15: =IF(D15=0,0,(D15-E15)/D15)
A16: 0004 · LED Background — Custom resolution | B16: Couple-specified pixel dimensions | C16: For LED walls that don't fit standard ratios. Couple inputs exact pixel dimensions (e.g., 5760×1080 ultrawide). Renderer adapts viewBox. | D16: 899 | E16: 90 | F16: =D16-E16 | G16: =IF(D16=0,0,(D16-E16)/D16)
... A32: ADD-ON · Personal Reel Template | B32: Per template unlock for guests | C32: Couple unlocks a template; guests can use it to build their 30s souvenir reel. Cost = ~₱2 per render × ~30 reels = ~₱60. | D32: 599 | E32: 60 | F32: =D32-E32 | G32: =IF(D32=0,0,(D32-E32)/D32)
A35: Notes & assumptions
A36: • All prices in PHP. Costs are estimated marginal cost per unit at small-to-mid scale (≤300 weddings/year).
A37: • Couple price values are inputs (BLUE) — change them to recalculate margin. Cost values are also inputs (BLUE).
A38: • Margin and Margin % cells are formulas (BLACK) — automatically recalculate when inputs change.
A39: • 'Included in base tier' rows show ₱0 in price column — these features ship with any Paparazzi tier purchase.
A40: • TBD pricing rows are placeholders for iterations whose monetization isn't locked yet.
A41: • LED Background costs assume FFmpeg + Lottie + free-tier Cloudflare Containers stack. Higher volume may push compute costs up.
A42: • Paparazzi tier costs (₱195 / ₱265) are sourced from existing CLAUDE.md decision log.

Sheet Cost Breakdown
A1: Per-SKU cost breakdown — what we spend per unit delivered
A2: All amounts in PHP. BLUE cells are inputs you can change.
A4: SKU | B4: Cost component | C4: Amount per unit (₱) | D4: Notes
A5: 3 Paparazzi tier · ₱1,499
B6: R2 storage (5-year retention, ~5 GB photos) | C6: 80 | D6: Cloudflare R2: $0.015/GB/month × 60 months × 5 GB ≈ $4.50 ≈ ₱260 over lifetime; amortized per event ≈ ₱80
B7: Backend hosting & DB amortized per event | C7: 60 | D7: Cloudflare Workers + D1/Postgres + Queue, amortized over couples per month
B8: Native app token + ICS / OG render compute | C8: 25 | D8: Per-event QR generation + invitation OG image render
B9: Email (Resend) for invitations + reminders | C9: 15 | D9: ~50-100 emails per event at ~₱0.20 each
B10: Misc (analytics, error monitoring, support) | C10: 15 | D10: Allocated overhead per event
A11: 3 Paparazzi · TOTAL COST | C11: 195 | D11: ₱195 cost on ₱1,999 price = 90.2% margin (₱1,804 per event)
A12: 5 Paparazzi tier · ₱2,499
B13: R2 storage (5-year retention, ~8 GB photos) | C13: 130 | D13: More photographers = more photos = more storage; ₱260/event over lifetime ÷ amortized
B14: Backend hosting & DB amortized per event | C14: 70 | D14: Slightly higher footprint due to higher photo volume
B15: Native app tokens (5) + ICS / OG render compute | C15: 30 | D15: 5 paparazzi tokens vs 3
B16: Email (Resend) for invitations + reminders | C16: 15 | D16: Similar count regardless of paparazzi tier
B17: Misc (analytics, error monitoring, support) | C17: 20 | D17: Slightly more support inquiries on larger events
A18: 5 Paparazzi · TOTAL COST | C18: 265 | D18: ₱265 cost on ₱2,999 price = 91.2% margin (₱2,734 per event)
A19: Personal Reel Template · ₱199
B20: FFmpeg compute per reel render | C20: 2 | D20: Cloudflare Container ~₱2 per 30s render
B21: Per-couple usage (avg ~30 reels per event) | C21: 60 | D21: ₱2 × ~30 guest renders typically
A22: Reel Template · TOTAL COST | C22: 60 | D22: ₱60 cost on ₱599 price = 90.0% margin (₱539 per template unlock)
A23: Pro Hero Monogram animation · ₱99
B24: CSS/SVG animation (pre-programmed, no per-event cost) | C24: 0 | D24: Animation is client-side; zero marginal cost to deliver
B25: Storage of animated SVG | C25: 0 | D25: Negligible — same payload as static SVG
A26: Pro Monogram · TOTAL COST | C26: 0 | D26: 100% margin — pure pre-programmed enhancement
A27: Pro Venue Waze · ₱99
B28: URL-formatting helper (free) | C28: 0 | D28: Waze + Google Maps deep-links are URL-only; no API cost
A29: Pro Venue Waze · TOTAL COST | C29: 0 | D29: 100% margin — pure pre-programmed enhancement
A30: Pro Bundle · ₱149
B31: Same pre-programmed enhancements as Pro upgrades | C31: 0 | D31: Both Hero animation + Venue Waze are pre-programmed
A32: Pro Bundle · TOTAL COST | C32: 0 | D32: 100% margin
A33: LED Background · 1080p · ₱99
B34: Cloudflare Container compute (~3 min) | C34: 8 | D34: $0.0001/sec × 180s ≈ ₱1; with 5x markup buffer ₱8
B35: FFmpeg encoding overhead | C35: 5 | D35: Encoding adds CPU cost beyond render
B36: R2 storage of output (~30 MB) for 1 year | C36: 1 | D36: ~₱0.50/MB/year × 30 MB ÷ amortized
B37: Stock overlay license amortized per render | C37: 5 | D37: ₱5,000 one-time stock pack ÷ ~1,000 renders lifetime
B38: Lottie template license amortized | C38: 6 | D38: Avg ₱5,000 per template ÷ ~1,000 lifetime renders
A39: LED 1080p · TOTAL COST | C39: 25 | D39: ₱25 cost on ₱249 price = 90.0% margin (₱224 per render)
A40: LED Background · 4K · ₱149
B41: Cloudflare Container compute (~5 min) | C41: 13 | D41: Higher resolution = longer render
...

Sheet One-Time Setup
A1: One-time investments to launch — amortizable over expected unit volume
A2: These costs are paid once and amortized into per-unit cost on the 'Cost Breakdown' sheet.
A4: Iteration | B4: What we buy | C4: One-time cost (₱) | D4: Expected lifetime units | E4: Per-unit amortized (₱)
A5: 0001 · Guest List | B5: Filipino role taxonomy + UI design refinement | C5: 0 | D5: 1000 | E5: 0
A6: 0002 · QR System | B6: qrcode npm package (free) + R2 storage setup | C6: 0 | D6: 1000 | E6: 0
A7: 0002 · QR System | B7: Custom QR finder pattern design | C7: 5000 | D7: 1000 | E7: =C7/D7
A8: 0003 · Widgets Editor | B8: 10 widget designs (engineering) | C8: 0 | D8: 1000 | E8: 0
A9: 0003 · Widgets Editor | B9: Pro animation pre-programming (Hero + Venue) | C9: 0 | D9: 1000 | E9: 0
A10: 0004 · LED Background Maker | B10: Stock overlay pack (Motion Array / Envato) | C10: 5000 | D10: 1000 | E10: =C10/D10
A11: 0004 · LED Background Maker | B11: Lottie template licenses (5 templates × ₱500-2000) | C11: 7500 | D11: 1000 | E11: =C11/D11
A12: 0004 · LED Background Maker | B12: Custom Lottie templates (5 templates × ₱25k motion designer) | C12: 125000 | D12: 1000 | E12: =C12/D12
A13: 0004 · LED Background Maker | B13: Motion designer consultation (1-hour) | C13: 5000 | D13: 1000 | E13: =C13/D13
A14: 0004 · LED Background Maker | B14: FFmpeg + Lottie pipeline engineering setup | C14: 0 | D14: 1000 | E14: 0
A15: 0008 · Photo Delivery | B15: Google OAuth verification (Setnayan app review with Google) | C15: 0 | D15: 5000 | E15: 0
A16: Music catalogue · per CLAUDE.md | B16: Suno Premier annual subscription (~₱150K saved) | C16: 36000 | D16: 5000 | E16: =C16/D16
A17: Template library (Paparazzi reels) | B17: 400 templates pre-generated × generation cost | C17: 50000 | D17: 30000 | E17: =C17/D17
A19: TOTAL one-time investment | C19: =SUM(C5:C17)

Sheet Margin Analysis
A1: Margin per SKU — quick scan of profitability
A2: Cells with green text are formulas; blue cells are direct inputs from Pricing Overview.
A4: SKU | B4: Couple price (₱) | C4: Cost (₱) | D4: Margin (₱) | E4: Margin % | F4: Estimated demand factor
A5: Hero Monogram Pro animation | B5: ='Pricing Overview'!D9 | C5: ='Pricing Overview'!E9 | D5: =B5-C5 | E5: =IF(B5=0,0,(B5-C5)/B5) | F5: Medium
A6: Venue Pro Waze deep-links | B6: ='Pricing Overview'!D10 | C6: ='Pricing Overview'!E10 | D6: =B6-C6 | E6: =IF(B6=0,0,(B6-C6)/B6) | F6: Medium
A7: Pro Bundle | B7: ='Pricing Overview'!D11 | C7: ='Pricing Overview'!E11 | D7: =B7-C7 | E7: =IF(B7=0,0,(B7-C7)/B7) | F7: High
A8: LED Background — 1080p | B8: ='Pricing Overview'!D13 | C8: ='Pricing Overview'!E13 | D8: =B8-C8 | E8: =IF(B8=0,0,(B8-C8)/B8) | F8: Medium
A9: LED Background — 4K | B9: ='Pricing Overview'!D14 | C9: ='Pricing Overview'!E14 | D9: =B9-C9 | E9: =IF(B9=0,0,(B9-C9)/B9) | F9: High
A10: LED Background — 8K | B10: ='Pricing Overview'!D15 | C10: ='Pricing Overview'!E15 | D10: =B10-C10 | E10: =IF(B10=0,0,(B10-C10)/B10) | F10: Medium-High
A11: BASE TIER · 3 Paparazzi | B11: ='Pricing Overview'!D19 | C11: ='Pricing Overview'!E19 | D11: =B11-C11 | E11: =IF(B11=0,0,(B11-C11)/B11) | F11: High
A12: BASE TIER · 5 Paparazzi | B12: ='Pricing Overview'!D20 | C12: ='Pricing Overview'!E20 | D12: =B12-C12 | E12: =IF(B12=0,0,(B12-C12)/B12) | F12: Medium-High
A13: ADD-ON · Personal Reel Template | B13: ='Pricing Overview'!D21 | C13: ='Pricing Overview'!E21 | D13: =B13-C13 | E13: =IF(B13=0,0,(B13-C13)/B13) | F13: High (per template per event)

Sheet Read Me
A1: How to read this workbook
A3: Pricing Overview | B3: Master view: every iteration's products, what couples pay, what we spend, automatic margin calculation. Start here.
A4: Cost Breakdown | B4: Drill-down per SKU: every cost component (compute, storage, content amortization, etc.) that adds up to the per-unit cost on the master sheet.
A5: One-Time Setup | B5: Up-front investments that get amortized into the per-unit cost. E.g., a ₱125,000 motion designer fee for 5 custom Lottie templates becomes ₱125 per render over 1,000 expected renders.
A6: Margin Analysis | B6: Quick profitability scan. Margin % is conditionally color-graded (red = low, green = high) so you can spot the most profitable SKUs.
A8: Color conventions | B8: BLUE text = hardcoded input you can change (price, cost). BLACK text = formula. GREEN text = link to another sheet. The model recalculates automatically when inputs change.
A10: Pricing decisions captured | B10: All prices in this workbook reflect the locked pricing as of 2026-05-08:
B11: • 0003 Pro widgets: Hero Monogram animation ₱99, Venue Waze ₱99, Pro Bundle ₱149
B12: • 0004 LED renders: 1080p ₱249, 4K ₱399, 8K ₱599 per render
B13: • 0008 Photo Delivery to Drive: ₱99 per event
B14: • Base tiers: 3 Paparazzi ₱1,999, 5 Paparazzi ₱2,999
B15: • Personal Reel Template add-on: ₱599 per template unlock
B16: • All upgrades target ~90% gross margin at small-to-mid scale (≤300 weddings/year)
A18: Iterations awaiting pricing | B18: 0005 Vendors, 0006 Budget, 0007 Seating Chart, 0009 Mood Board are placeholder specs — pricing will be added when those iterations are built in full.
A20: Per-unit costs are estimates | B20: Cost figures assume FFmpeg + Lottie + Cloudflare free-tier infrastructure. Volume scaling (>300 weddings/year) may shift these costs slightly upward.
A22: To update prices | B22: Edit the BLUE cells on Pricing Overview. Margins recalculate automatically. To update the breakdown of how costs add up, edit the Cost Breakdown sheet.
